<mujoco model="humanoid_collision">

    <size njmax='5000' nconmax='5000'/>

    <include file="assets/humanoid.xml"/>

    <visual>
    <global offwidth="2560" offheight="1920" />
    <quality shadowsize="4096" offsamples="8" />
    <map force="0.1" fogend="5" />
    </visual>

    <!-- <compiler inertiafromgeom='auto' inertiagrouprange='3 5' angle="radian" texturedir="textures" meshdir="../franka_assets/meshes"/> -->
    <compiler angle="degree" inertiafromgeom="true"/>
    <worldbody>
        <camera name='left_cap' pos='-1.2 -0.5 1.8' quat='0.78 0.49 -0.22 -0.32' />
        <camera name='right_cap' pos='1.2 -0.5 1.8' quat='0.76 0.5 0.21 0.35'/>

        <body name='dump_car' pos='3 0 0.5'>
    		<geom name="car" type="box" pos="0 0 0" rgba="1.0 1.0 1.0 1.0" size="1 0.5 0.5" mass="1" contype="3" conaffinity="1"></geom>
			<joint name="car_x" axis="1 0 0" range="-100 100" type="slide"></joint>
			<joint name="car_y" axis="0 0 1" range="-1800 1800" type="hinge"></joint>
        </body>
    </worldbody>


    <actuator>
		<motor name="vel_car_x" ctrlrange="-500 0" gear="1000" joint="car_x"/>
		<motor name="vel_car_y" ctrlrange="-500 500" gear="1000" joint="car_y"/>
    </actuator>

    <keyframe>
        <key time="0" name="init_1" qpos='0 0 1.28572 1 0 0 0 0 0.06545 0.000654416 -0.000519518 0.000295813 -0.0287039 -0.148354 0.000723226 0.000288589 -0.0262428 -0.143245 0.214862 -0.140007 -0.0754472 -0.214553 0.140187 -0.0754199 0 0'/>
        <key time="1" name="init_2" qpos='0 0 1.28572 1 0 0 1 0 0.06545 0.000654416 -0.000519518 0.000295813 -0.0287039 -0.148354 0.000723226 0.000288589 -0.0262428 -0.143245 0.214862 -0.140007 -0.0754472 -0.214553 0.140187 -0.0754199 0 0'/>
        <key time="2" name="init_3" qpos='0 0 1.28572 1 0 0 2 0 0.06545 0.000654416 -0.000519518 0.000295813 -0.0287039 -0.148354 0.000723226 0.000288589 -0.0262428 -0.143245 0.214862 -0.140007 -0.0754472 -0.214553 0.140187 -0.0754199 0 0'/>
        <key time="3" name="init_4" qpos='0 0 1.28572 1 0 0 -1 0 0.06545 0.000654416 -0.000519518 0.000295813 -0.0287039 -0.148354 0.000723226 0.000288589 -0.0262428 -0.143245 0.214862 -0.140007 -0.0754472 -0.214553 0.140187 -0.0754199 0 0'/>
        <key time="4" name="init_5" qpos='0 0 1.28572 1 0 0 -2 0 0.06545 0.000654416 -0.000519518 0.000295813 -0.0287039 -0.148354 0.000723226 0.000288589 -0.0262428 -0.143245 0.214862 -0.140007 -0.0754472 -0.214553 0.140187 -0.0754199 0 0'/>
        <key time="5" name="stand" qpos='0.133918 -0.0218745 1.19787 0.940614 -0.0140571 0.322482 -0.105132 -0.0622136 -0.0692509 0.164579 -0.00532302 0.00498885 -0.703961 -0.0225129 -0.000738711 -0.00781844 -0.68344 -0.0190305 0.464879 0.18362 -1.57172 -0.599386 0.14829 -1.57106 0 0'/>
        <key time="6" name="one_leg" qpos='0 0 1.28572 1 0 0 0 -6.93048e-05 -0.114761 0.000654416 -0.000519518 0.000295813 -1.56829 -1.67597 0.000723226 0.000288589 -0.0262428 -0.143245 0.7939 -0.52222 -1.571 -0.7939 0.52222 -1.571 0 0'/>
        <key time="7" name="walking_1" qpos='0 0 1.15218 0.704789 0 0 0.709417 -0.0213519 0.010472 -0.0364225 0.0969587 0.0575317 -0.864868 -0.669271 -0.0103317 -0.059692 0.3491 -0.503785 1.047 -1.30683 -1.31441 -0.390818 0.0362636 -1.31161 0 0'/>
        <key time="8" name="walking_2" qpos='0 0 1.15218 -0.909417 0 0 0.709417 0.7854 0.010472 -0.0364225 0.0969587 0.0575317 -0.864868 -0.669271 -0.0103317 -0.059692 0.3491 -0.503785 1.047 -1.30683 -1.31441 -0.390818 0.0362636 -1.31161 0 0'/>
        <key time="9" name="walking_3" qpos='0 0 1.15218 -0.609417 0 0 0.709417 0.7854 0.010472 -0.0364225 0.0969587 0.0575317 -0.864868 -0.669271 -0.0103317 -0.059692 0.3491 -0.503785 1.047 -1.30683 -1.31441 -0.390818 0.0362636 -1.31161 0 0'/>
        <key time="10" name="walking_4" qpos='0 0 1.15218 -0.309417 0 0 0.709417 0.7854 0.010472 -0.0364225 0.0969587 0.0575317 -0.864868 -0.669271 -0.0103317 -0.059692 0.3491 -0.503785 1.047 -1.30683 -1.31441 -0.390818 0.0362636 -1.31161 0 0'/>
        <key time="11" name="walking_5" qpos='0 0 1.15218 0.309417 0 0 0.709417 0.7854 0.010472 -0.0364225 0.0969587 0.0575317 -0.864868 -0.669271 -0.0103317 -0.059692 0.3491 -0.503785 1.047 -1.30683 -1.31441 -0.390818 0.0362636 -1.31161 0 0'/>
        <key time="12" name="walking_6" qpos='0 0 1.15218 0.609417 0 0 0.709417 0.7854 0.010472 -0.0364225 0.0969587 0.0575317 -0.864868 -0.669271 -0.0103317 -0.059692 0.3491 -0.503785 1.047 -1.30683 -1.31441 -0.390818 0.0362636 -1.31161 0 0'/>

        <key time="13" name="surprise_1" qpos='-0.0247077 -0.000554168 1.28613 1 0 0 0 4.20628e-05 -0.0776927 0.000107764 -0.0015404 0.000707295 -0.0126417 -0.21985 0.00177397 0.000678935 -0.00984868 -0.211776 -1.05052 0.517307 -1.4879 1.06716 -0.439106 -1.4884 0 0'/>
        <key time="14" name="surprise_2" qpos='-0.0580248 -0.00317346 1.16502 0.999982 -0.00441152 -0.00016676 0.00394072 -4.14041e-05 -0.266755 0.0144528 -0.438733 0.100592 -0.111054 -0.777751 -0.440153 0.0967707 -0.109151 -0.744821 -0.559966 0.391627 -1.46381 0.597003 -0.33199 -1.46568 0 0'/>
        <key time="15" name="surprise_3" qpos='-0.0804532 0.0102183 0.838432 0.996145 -0.0223562 -0.0652728 0.0541826 0.0082079 -0.383359 -0.0252497 -0.0198007 -0.0195727 -1.07999 -1.87852 -0.0169261 0.0553656 0.245456 -1.93946 0.7051 -0.456283 -1.57155 -0.682847 0.380951 -1.57126 0.000180682 0.000591009'/>
        <key time="16" name="defense_1" qpos='-0.0247077 -0.000554168 1.28613 1 0 0 0 4.20628e-05 -0.0776927 0.000107764 -0.0015404 0.000707295 -1.92 -0.903708 0.00177397 0.000678935 -0.00984868 -0.211776 -0.028675 1.047 -1.571 0.155225 -1.047 -1.571 0 0'/>
        <key time="17" name="defense_2" qpos='-0.0247077 -0.000554168 1.28613 1 0 0 0 4.20628e-05 -0.0776927 0.000107764 -0.0015404 0.000707295 -1.62502 -1.82767 0.00177397 0.000678935 -0.00984868 -0.03491 0.2877 0.426905 -1.571 0.155225 -0.705315 -1.571 0 0'/>
        <key time="18" name="defense_3" qpos='0 0 1.15218 -0.788472 0 0 0.61507 0.7854 0.010472 -0.0364225 0.0969587 0.0575317 -0.864868 -0.669271 -0.0103317 -0.059692 0.3491 -0.503785 1.047 -1.30683 -1.31441 0.85125 0.534875 -1.571 0 0'/>
        <key time="19" name="defense_4"  qpos='0 0 1.28572 1 0 0 0 0 0.06545 0.000654416 -0.000519518 0.000295813 -0.0287039 -0.148354 0.000723226 0.000288589 -0.0262428 -0.143245 0.755935 0.604075 -1.571 0.155225 -1.047 -1.571 0 0'/>

        <key time="20" name="test" qpos=' 0 0 1.28572 1 0 0 0 0 0.42813881 0 -0.43633231 0  -0.83914233 -1.12583651 -0.43414364 0  -0.69201463 -1.73617797 -0.28624896 -0.896553 0.33814117 0.08905295 0.54203417 0.29885724 0 0'/>

        <key time="21" name="corrected" qpos='0.0578824 -0.00103405 1.10093 1 -2.86229e-17 3.38271e-17 -1.73472e-18 0 0.428139 0 -0.436332 0 -0.839142 -1.12584 -0.434144 0 -0.692015 -1.73618 -0.286249 -0.896553 0.338141 0.089053 0.542034 0.298857 0 0'/>
    </keyframe>
</mujoco>

